Workbook

Sheet Pipeline_Activity_Data
A1: Case ID | B1: Tanggal | C1: Periode | D1: Minggu | E1: Region | F1: Area | G1: Cabang | H1: Supervisor | I1: Sales | J1: NIP Sales | K1: Produk | L1: Sumber Pipeline | M1: Segment Nasabah | N1: Stage Pipeline | O1: Stage Score | P1: Activity | Q1: Jenis Activity | R1: Tanggal Follow Up Terakhir | S1: Aging Pipeline | T1: Plafond | U1: Status Cair | V1: Status Dokumen | W1: Kendala | X1: Alasan Batal Reject | Y1: Next Action | Z1: Keterangan | AA1: Quality Tag | AB1: Risiko | AC1: Expected Insight Label
A2: CASE-00001 | B2: 46202 | C2: 2026-06 | D2: W5 | E2: RO JAKARTA 1 | F2: JAKARTA UTARA | G2: KCP KELAPA GADING | H2: SPV Kartika Nugroho | I2: Taufik Pertiwi | J2: S0303004 | K2: Pensiun Berkah | L2: Event Sosialisasi | M2: Pensiunan | N2: Dingin | O2: 2 | P2: 2 | Q2: Kunjungan | R2: 46198 | S2: 5 | T2: 135000000 | U2: Belum Cair | V2: Belum Ada | W2: Perlu edukasi manfaat | Y2: Follow-up berkala | Z2: Pipeline awal + activity rendah. | AA2: Pipeline awal dominan | AB2: Pipeline awal + activity rendah | AC2: Pipeline awal dominan
A3: CASE-00002 | B3: 46195 | C3: 2026-06 | D3: W4 | E3: RO BANDUNG | F3: GARUT | G3: KC CIMAHI | H3: SPV Dimas Wijaya | I3: Fajar Utami | J3: S0503006 | K3: Pensiun Berkah | L3: Telemarketing | M3: Pra Pensiun | N3: Hangat | O3: 3 | P3: 10 | Q3: Koordinasi Cabang | R3: 46190 | S3: 13 | T3: 98000000 | U3: Belum Cair | V3: Sebagian | W3: Menunggu keputusan keluarga | Y3: Follow-up komitmen | Z3: Butuh penguatan follow-up. | AA3: Konversi cukup baik | AB3: Butuh penguatan follow-up | AC3: Konversi cukup baik
A4: CASE-00003 | B4: 46199 | C4: 2026-06 | D4: W4 | E4: RO BANDUNG | F4: GARUT | G4: KC BANDUNG | H4: SPV Hani Kusuma | I4: Bella Nugroho | J4: S0502004 | K4: Pensiun Berkah | L4: Nasabah Eksisting | M4: Pra Pensiun | N4: Hangat | O4: 3 | P4: 10 | Q4: Reminder Pemberkasan | R4: 46190 | S4: 13 | T4: 188000000 | U4: Belum Cair | V4: Lengkap | W4: Perlu simulasi angsuran | Y4: Handling objection | Z4: Butuh penguatan follow-up. | AA4: Konversi cukup baik | AB4: Butuh penguatan follow-up | AC4: Konversi cukup baik
A5: CASE-00004 | B5: 46189 | C5: 2026-06 | D5: W3 | E5: RO SEMARANG | F5: SEMARANG KOTA | G5: KC SOLO | H5: SPV Nabila Anggraini | I5: Nabila Saputra | J5: S0601007 | K5: Pensiun Berkah | L5: Database Internal | M5: BUMN | N5: Tidak Bertemu | O5: 1 | P5: 5 | Q5: Follow-up WA | R5: 46180 | S5: 23 | T5: 229000000 | U5: Belum Cair | V5: Belum Ada | W5: Nasabah belum dapat dihubungi | Y5: Cek database alternatif | Z5: Perlu monitoring. | AA5: Pipeline menengah berkembang | AB5: Perlu monitoring | AC5: Pipeline menengah berkembang
A6: CASE-00005 | B6: 46195 | C6: 2026-06 | D6: W4 | E6: RO BANDUNG | F6: BANDUNG KOTA | G6: KC BANDUNG | H6: SPV Eka Saputra | I6: Lukman Santoso | J6: S0501005 | K6: Pensiun Reguler | L6: Event Sosialisasi | M6: Swasta | N6: Panas | O6: 4 | P6: 14 | Q6: Reminder Pemberkasan | R6: 46187 | S6: 16 | T6: 171000000 | U6: Belum Cair | V6: Sebagian | W6: Menunggu jadwal collect dokumen | Y6: Konfirmasi komitmen | Z6: Bottleneck tahap akhir. | AA6: Konversi cukup baik | AB6: Bottleneck tahap akhir | AC6: Konversi cukup baik
A7: CASE-00006 | B7: 46181 | C7: 2026-06 | D7: W2 | E7: RO SURABAYA 1 | F7: SURABAYA KOTA | G7: KC GRESIK | H7: SPV Lukman Lestari | I7: Yoga Pertiwi | J7: S0702006 | K7: Mitraguna | L7: Nasabah Eksisting | M7: ASN | N7: Panas | O7: 4 | P7: 15 | Q7: Validasi Data | R7: 46177 | S7: 26 | T7: 100000000 | U7: Belum Cair | V7: Sebagian | W7: Menunggu jadwal collect dokumen | Y7: Eskalasi jika tertahan | Z7: Bottleneck tahap akhir. | AA7: High performer | AB7: Bottleneck tahap akhir | AC7: High performer
A8: CASE-00007 | B8: 46183 | C8: 2026-06 | D8: W2 | E8: RO MAKASSAR | F8: MAROS | G8: KCP PANAKKUKANG | H8: SPV Dewi Aulia | I8: Dimas Santoso | J8: S0801007 | K8: Top Up Pensiun | L8: Nasabah Eksisting | M8: ASN | N8: Panas | O8: 4 | P8: 11 | Q8: Follow-up WA | R8: 46177 | S8: 26 | T8: 190000000 | U8: Belum Cair | V8: Sebagian | W8: Menunggu jadwal collect dokumen | X8: Menunggu kelengkapan dokumen | Y8: Eskalasi jika tertahan | Z8: Bottleneck tahap akhir. | AA8: Pipeline matang stabil | AB8: Bottleneck tahap akhir | AC8: Pipeline matang stabil
A9: CASE-00008 | B9: 46201 | C9: 2026-06 | D9: W4 | E9: RO ACEH | F9: BANDA ACEH | G9: KC BANDA ACEH | H9: SPV Jihan Fauzi | I9: Rizal Pratama | J9: S0102005 | K9: Pra Pensiun | L9: Telemarketing | M9: Pensiunan | N9: Tidak Bertemu | O9: 1 | P9: 6 | Q9: Kunjungan | R9: 46194 | S9: 9 | T9: 284000000 | U9: Belum Cair | V9: Belum Ada | W9: Nasabah belum dapat dihubungi | Y9: Cek database alternatif | Z9: Perlu monitoring. | AA9: Bottleneck tahap akhir | AB9: Perlu monitoring | AC9: Bottleneck tahap akhir
A10: CASE-00009 | B10: 46198 | C10: 2026-06 | D10: W4 | E10: RO MAKASSAR | F10: MAROS | G10: KC MAKASSAR | H10: SPV Citra Hidayat | I10: Putri Rahman | J10: S0802002 | K10: Mitraguna | L10: Telemarketing | M10: Payroll | N10: Pemberkasan | O10: 5 | P10: 9 | Q10: Reminder Pemberkasan | R10: 46198 | S10: 5 | T10: 67000000 | U10: Belum Cair | V10: Lengkap | W10: Menunggu proses administrasi | Y10: Lengkapi berkas | Z10: Bottleneck tahap akhir. | AA10: Pipeline matang stabil | AB10: Bottleneck tahap akhir | AC10: Pipeline matang stabil
A11: CASE-00010 | B11: 46176 | C11: 2026-06 | D11: W1 | E11: RO ACEH | F11: BANDA ACEH | G11: KCP SAKTI | H11: SPV Hendra Pratama | I11: Gita Ananda | J11: S0101003 | K11: Mitraguna | L11: Event Sosialisasi | M11: Pensiunan | N11: Hangat | O11: 3 | P11: 7 | Q11: Collect Dokumen | R11: 46167 | S11: 36 | T11: 223000000 | U11: Belum Cair | V11: Lengkap | W11: Perlu simulasi angsuran | Y11: Handling objection | Z11: Butuh penguatan follow-up. | AA11: Bottleneck tahap akhir | AB11: Butuh penguatan follow-up | AC11: Bottleneck tahap akhir
A12: CASE-00011 | B12: 46196 | C12: 2026-06 | D12: W4 | E12: RO SURABAYA 1 | F12: SIDOARJO | G12: KC GRESIK | H12: SPV Lukman Lestari | I12: Jihan Permata | J12: S0702001 | K12: Pensiun Reguler | L12: Nasabah Eksisting | M12: Pra Pensiun | N12: Pemberkasan | O12: 5 | P12: 16 | Q12: Follow-up Telepon | R12: 46194 | S12: 9 | T12: 236000000 | U12: Belum Cair | V12: Perlu Revisi | W12: Dokumen pendukung belum lengkap | X12: Menunggu kelengkapan dokumen | Y12: Lengkapi berkas | Z12: Bottleneck tahap akhir. | AA12: High performer | AB12: Bottleneck tahap akhir | AC12: High performer
A13: CASE-00012 | B13: 46184 | C13: 2026-06 | D13: W2 | E13: RO SURABAYA 1 | F13: GRESIK | G13: KCP WARU | H13: SPV Taufik Rahman | I13: Vina Lestari | J13: S0703005 | K13: Pra Pensiun | L13: Sapa Kebun | M13: BUMN | N13: Panas | O13: 4 | P13: 16 | Q13: Koordinasi Cabang | R13: 46182 | S13: 21 | T13: 235000000 | U13: Belum Cair | V13: Sebagian | W13: Menunggu jadwal collect dokumen | Y13: Konfirmasi komitmen | Z13: Bottleneck tahap akhir. | AA13: High performer | AB13: Bottleneck tahap akhir | AC13: High performer
A14: CASE-00013 | B14: 46195 | C14: 2026-06 | D14: W4 | E14: RO JAKARTA 2 | F14: JAKARTA TIMUR | G14: KC BEKASI | H14: SPV Kurnia Pratama | I14: Sinta Maulana | J14: S0401001 | K14: Pensiun Berkah | L14: Telemarketing | M14: Swasta | N14: Hangat | O14: 3 | P14: 11 | Q14: Kunjungan | R14: 46186 | S14: 17 | T14: 213000000 | U14: Belum Cair | V14: Sebagian | W14: Butuh follow-up lanjutan | Y14: Tetapkan next step | Z14: Butuh penguatan follow-up. | AA14: Activity tinggi namun hasil rendah | AB14: Butuh penguatan follow-up | AC14: Activity tinggi namun hasil rendah
A15: CASE-00014 | B15: 46198 | C15: 2026-06 | D15: W4 | E15: RO SEMARANG | F15: KUDUS | G15: KCP UNGARAN | H15: SPV Nabila Anggraini | I15: Zaki Pratama | J15: S0601002 | K15: Mitraguna | L15: Telemarketing | M15: Non Payroll | N15: Hangat | O15: 3 | P15: 8 | Q15: Koordinasi Cabang | R15: 46190 | S15: 13 | T15: 162000000 | U15: Belum Cair | V15: Sebagian | W15: Perlu simulasi angsuran | Y15: Simulasi angsuran | Z15: Butuh penguatan follow-up. | AA15: Pipeline menengah berkembang | AB15: Butuh penguatan follow-up | AC15: Pipeline menengah berkembang
A16: CASE-00015 | B16: 46175 | C16: 2026-06 | D16: W1 | E16: RO ACEH | F16: ACEH TIMUR | G16: KCP SAKTI | H16: SPV Hendra Pratama | I16: Dimas Saputra | J16: S0101005 | K16: Pra Pensiun | L16: Walk-in | M16: ASN | N16: Panas | O16: 4 | P16: 12 | Q16: Collect Dokumen | R16: 46171 | S16: 32 | T16: 124000000 | U16: Belum Cair | V16: Sebagian | W16: Menunggu komitmen nasabah | Y16: Eskalasi jika tertahan | Z16: Bottleneck tahap akhir. | AA16: Bottleneck tahap akhir | AB16: Bottleneck tahap akhir | AC16: Bottleneck tahap akhir
A17: CASE-00016 | B17: 46187 | C17: 2026-06 | D17: W2 | E17: RO MEDAN | F17: DELI SERDANG | G17: KCP MARELAN | H17: SPV Ulfa Saputra | I17: Ulfa Lestari | J17: S0203004 | K17: Mitraguna | L17: Database Internal | M17: Payroll | N17: Dingin | O17: 2 | P17: 3 | Q17: Follow-up Telepon | R17: 46183 | S17: 20 | T17: 106000000 | U17: Tidak Cair | V17: Belum Ada | W17: Minat masih rendah | X17: BI Checking | Y17: Segmentasi ulang prospek | Z17: Pipeline awal + activity rendah. | AA17: Kinerja seimbang | AB17: Pipeline awal + activity rendah | AC17: Kinerja seimbang
A18: CASE-00017 | B18: 46199 | C18: 2026-06 | D18: W4 | E18: RO SEMARANG | F18: SOLO | G18: KC SEMARANG | H18: SPV Sinta Aulia | I18: Naufal Pertiwi | J18: S0603007 | K18: Top Up Pensiun | L18: Referal Cabang | M18: Non Payroll | N18: Panas | O18: 4 | P18: 8 | Q18: Koordinasi Cabang | R18: 46189 | S18: 14 | T18: 189000000 | U18: Belum Cair | V18: Sebagian | W18: Perlu validasi plafond | Y18: Eskalasi jika tertahan | Z18: Bottleneck tahap akhir. | AA18: Pipeline menengah berkembang | AB18: Bottleneck tahap akhir | AC18: Pipeline menengah berkembang
A19: CASE-00018 | B19: 46187 | C19: 2026-06 | D19: W2 | E19: RO MAKASSAR | F19: GOWA | G19: KCP PANAKKUKANG | H19: SPV Lina Maulana | I19: Galih Syahputra | J19: S0803005 | K19: Pensiun Berkah | L19: Event Sosialisasi | M19: Payroll | N19: Dingin | O19: 2 | P19: 12 | Q19: Collect Dokumen | R19: 46182 | S19: 21 | T19: 247000000 | U19: Belum Cair | V19: Sebagian | W19: Perlu edukasi manfaat | Y19: Segmentasi ulang prospek | Z19: Activity tinggi belum cair. | AA19: Pipeline matang stabil | AB19: Activity tinggi belum cair | AC19: Pipeline matang stabil
A20: CASE-00019 | B20: 46187 | C20: 2026-06 | D20: W2 | E20: RO MEDAN | F20: BINJAI | G20: KCP MARELAN | H20: SPV Ulfa Saputra | I20: Ulfa Lestari | J20: S0203004 | K20: Pra Pensiun | L20: Nasabah Eksisting | M20: Swasta | N20: Cair | O20: 7 | P20: 12 | Q20: Koordinasi Cabang | R20: 46182 | S20: 21 | T20: 191000000 | U20: Cair | V20: Lengkap | W20: Dokumen selesai | Y20: Dokumentasi realisasi | Z20: Terkonversi. | AA20: Kinerja seimbang | AB20: Terkonversi | AC20: Kinerja seimbang
A21: CASE-00020 | B21: 46198 | C21: 2026-06 | D21: W4 | E21: RO SURABAYA 1 | F21: SURABAYA KOTA | G21: KC GRESIK | H21: SPV Ulfa Permata | I21: Ulfa Aulia | J21: S0701004 | K21: Pensiun Berkah | L21: Walk-in | M21: Payroll | N21: Hangat | O21: 3 | P21: 14 | Q21: Follow-up Telepon | R21: 46192 | S21: 11 | T21: 63000000 | U21: Belum Cair | V21: Belum Ada | W21: Nasabah masih mempertimbangkan | Y21: Simulasi angsuran | Z21: Activity tinggi belum cair. | AA21: High performer | AB21: Activity tinggi belum cair | AC21: High performer
A22: CASE-00021 | B22: 46181 | C22: 2026-06 | D22: W2 | E22: RO JAKARTA 2 | F22: JAKARTA SELATAN | G22: KC JAKARTA FATMAWATI | H22: SPV Yuni Nugroho | I22: Vina Pratama | J22: S0403004 | K22: Mitraguna | L22: Nasabah Eksisting | M22: BUMN | N22: Cair | O22: 7 | P22: 14 | Q22: Validasi Data | R22: 46179 | S22: 24 | T22: 398000000 | U22: Cair | V22: Lengkap | W22: Realisasi selesai | Y22: Maintenance nasabah | Z22: Terkonversi. | AA22: Activity tinggi namun hasil rendah | AB22: Terkonversi | AC22: Activity tinggi namun hasil rendah
A23: CASE-00022 | B23: 46189 | C23: 2026-06 | D23: W3 | E23: RO SURABAYA 1 | F23: SIDOARJO | G23: KCP MANYAR | H23: SPV Lukman Lestari | I23: Yoga Pertiwi | J23: S0702006 | K23: Pra Pensiun | L23: Database Internal | M23: BUMN | N23: Perjanjian | O23: 6 | P23: 16 | Q23: Reminder Pemberkasan | R23: 46182 | S23: 21 | T23: 322000000 | U23: Menunggu Pencairan | V23: Perlu Revisi | W23: Administrasi akhir belum selesai | Y23: Cek administrasi akhir | Z23: Bottleneck tahap akhir. | AA23: High performer | AB23: Bottleneck tahap akhir | AC23: High performer
A24: CASE-00023 | B24: 46189 | C24: 2026-06 | D24: W3 | E24: RO JAKARTA 1 | F24: JAKARTA UTARA | G24: KCP GROGOL | H24: SPV Kartika Nugroho | I24: Sinta Lestari | J24: S0303005 | K24: Pra Pensiun | L24: Nasabah Eksisting | M24: Non Payroll | N24: Panas | O24: 4 | P24: 4 | Q24: Koordinasi Cabang | R24: 46184 | S24: 19 | T24: 400000000 | U24: Belum Cair | V24: Sebagian | W24: Menunggu jadwal collect dokumen | Y24: Eskalasi jika tertahan | Z24: Bottleneck tahap akhir. | AA24: Pipeline awal dominan | AB24: Bottleneck tahap akhir | AC24: Pipeline awal dominan
A25: CASE-00024 | B25: 46190 | C25: 2026-06 | D25: W3 | E25: RO JAKARTA 2 | F25: BEKASI | G25: KC BEKASI | H25: SPV Yuni Nugroho | I25: Oscar Pratama | J25: S0403007 | K25: Pensiun Berkah | L25: Event Sosialisasi | M25: BUMN | N25: Hangat | O25: 3 | P25: 11 | Q25: Collect Dokumen | R25: 46181 | S25: 22 | T25: 187000000 | U25: Belum Cair | V25: Belum Ada | W25: Perlu simulasi angsuran | Y25: Tetapkan next step | Z25: Butuh penguatan follow-up. | AA25: Activity tinggi namun hasil rendah | AB25: Butuh penguatan follow-up | AC25: Activity tinggi namun hasil rendah
A26: CASE-00025 | B26: 46196 | C26: 2026-06 | D26: W4 | E26: RO ACEH | F26: BANDA ACEH | G26: KCP BANDAR BARU | H26: SPV Jihan Fauzi | I26: Vina Permata | J26: S0102007 | K26: Pra Pensiun | L26: Event Sosialisasi | M26: Pensiunan | N26: Hangat | O26: 3 | P26: 15 | Q26: Follow-up WA | R26: 46189 | S26: 14 | T26: 216000000 | U26: Belum Cair | V26: Sebagian | W26: Nasabah masih mempertimbangkan | Y26: Follow-up komitmen | Z26: Activity tinggi belum cair. | AA26: Bottleneck tahap akhir | AB26: Activity tinggi belum cair | AC26: Bottleneck tahap akhir
A27: CASE-00026 | B27: 46187 | C27: 2026-06 | D27: W2 | E27: RO ACEH | F27: ACEH TIMUR | G27: KC LHOKSEUMAWE | H27: SPV Hendra Pratama | I27: Gita Ananda | J27: S0101003 | K27: Pensiun Berkah | L27: Sapa Kebun | M27: Payroll | N27: Panas | O27: 4 | P27: 7 | Q27: Reminder Pemberkasan | R27: 46178 | S27: 25 | T27: 87000000 | U27: Belum Cair | V27: Sebagian | W27: Menunggu jadwal collect dokumen | Y27: Validasi dokumen | Z27: Bottleneck tahap akhir. | AA27: Bottleneck tahap akhir | AB27: Bottleneck tahap akhir | AC27: Bottleneck tahap akhir
A28: CASE-00027 | B28: 46187 | C28: 2026-06 | D28: W2 | E28: RO SEMARANG | F28: SOLO | G28: KC KUDUS | H28: SPV Nabila Anggraini | I28: Dewi Wijaya | J28: S0601001 | K28: Pensiun Berkah | L28: Referal Cabang | M28: Payroll | N28: Cair | O28: 7 | P28: 15 | Q28: Follow-up WA | R28: 46183 | S28: 20 | T28: 130000000 | U28: Terealisasi | V28: Lengkap | W28: Dokumen selesai | Y28: Maintenance nasabah | Z28: Terkonversi. | AA28: Pipeline menengah berkembang | AB28: Terkonversi | AC28: Pipeline menengah berkembang
A29: CASE-00028 | B29: 46195 | C29: 2026-06 | D29: W4 | E29: RO BANDUNG | F29: BANDUNG KOTA | G29: KCP DAGO | H29: SPV Dimas Wijaya | I29: Farah Ananda | J29: S0503003 | K29: Mitraguna | L29: Event Sosialisasi | M29: Payroll | N29: Hangat | O29: 3 | P29: 12 | Q29: Koordinasi Cabang | R29: 46195 | S29: 8 | T29: 214000000 | U29: Belum Cair | V29: Belum Ada | W29: Butuh follow-up lanjutan | Y29: Handling objection | Z29: Activity tinggi belum cair. | AA29: Konversi cukup baik | AB29: Activity tinggi belum cair | AC29: Konversi cukup baik
... A32: CASE-00031 | B32: 46203 | C32: 2026-06 | D32: W5 | E32: RO ACEH | F32: ACEH BARAT | G32: KCP BANDAR BARU | H32: SPV Hendra Pratama | I32: Fajar Mahendra | J32: S0101004 | K32: Mitraguna | L32: Sapa Kebun | M32: BUMN | N32: Perjanjian | O32: 6 | P32: 10 | Q32: Validasi Data | R32: 46194 | S32: 9 | T32: 337000000 | U32: Belum Cair | V32: Lengkap | W32: Menunggu jadwal pencairan | Y32: Pastikan tanda tangan | Z32: Bottleneck tahap akhir. | AA32: Bottleneck tahap akhir | AB32: Bottleneck tahap akhir | AC32: Bottleneck tahap akhir
A33: CASE-00032 | B33: 46187 | C33: 2026-06 | D33: W2 | E33: RO MAKASSAR | F33: GOWA | G33: KCP SUNGGUMINASA | H33: SPV Lina Maulana | I33: Galih Syahputra | J33: S0803005 | K33: Pensiun Berkah | L33: Nasabah Eksisting | M33: BUMN | N33: Pemberkasan | O33: 5 | P33: 7 | Q33: Collect Dokumen | R33: 46177 | S33: 26 | T33: 248000000 | U33: Belum Cair | V33: Perlu Revisi | W33: Berkas perlu revisi | X33: Menunggu jadwal proses | Y33: Koordinasi cabang | Z33: Bottleneck tahap akhir. | AA33: Pipeline matang stabil | AB33: Bottleneck tahap akhir | AC33: Pipeline matang stabil
A34: CASE-00033 | B34: 46176 | C34: 2026-06 | D34: W1 | E34: RO JAKARTA 1 | F34: JAKARTA PUSAT | G34: KC JAKARTA THAMRIN | H34: SPV Joko Wijaya | I34: Zaki Fauzi | J34: S0302003 | K34: Pensiun Reguler | L34: Telemarketing | M34: Swasta | N34: Pemberkasan | O34: 5 | P34: 4 | Q34: Follow-up Telepon | R34: 46166 | S34: 37 | T34: 220000000 | U34: Batal Cair | V34: Sebagian | W34: Dokumen pendukung belum lengkap | X34: Nasabah berubah keputusan | Y34: Monitor status pengajuan | Z34: Bottleneck tahap akhir. | AA34: Pipeline awal dominan | AB34: Bottleneck tahap akhir | AC34: Pipeline awal dominan
A35: CASE-00034 | B35: 46177 | C35: 2026-06 | D35: W1 | E35: RO MAKASSAR | F35: MAKASSAR KOTA | G35: KC GOWA | H35: SPV Dewi Aulia | I35: Vina Santoso | J35: S0801003 | K35: Pensiun Reguler | L35: Walk-in | M35: Non Payroll | N35: Panas | O35: 4 | P35: 5 | Q35: Collect Dokumen | R35: 46167 | S35: 36 | T35: 146000000 | U35: Belum Cair | V35: Sebagian | W35: Dokumen awal belum lengkap | Y35: Collect dokumen | Z35: Bottleneck tahap akhir. | AA35: Pipeline matang stabil | AB35: Bottleneck tahap akhir | AC35: Pipeline matang stabil
A36: CASE-00035 | B36: 46174 | C36: 2026-06 | D36: W1 | E36: RO BANDUNG | F36: GARUT | G36: KCP SOREANG | H36: SPV Dimas Wijaya | I36: Rizal Nugroho | J36: S0503001 | K36: Mitraguna | L36: Nasabah Eksisting | M36: ASN | N36: Hangat | O36: 3 | P36: 12 | Q36: Validasi Data | R36: 46174 | S36: 29 | T36: 293000000 | U36: Belum Cair | V36: Belum Ada | W36: Perlu simulasi angsuran | Y36: Tetapkan next step | Z36: Activity tinggi belum cair. | AA36: Konversi cukup baik | AB36: Activity tinggi belum cair | AC36: Konversi cukup baik
A37: CASE-00036 | B37: 46194 | C37: 2026-06 | D37: W3 | E37: RO JAKARTA 1 | F37: JAKARTA BARAT | G37: KC JAKARTA THAMRIN | H37: SPV Kartika Nugroho | I37: Sinta Lestari | J37: S0303005 | K37: Pensiun Berkah | L37: Event Sosialisasi | M37: Non Payroll | N37: Panas | O37: 4 | P37: 6 | Q37: Follow-up WA | R37: 46184 | S37: 19 | T37: 127000000 | U37: Belum Cair | V37: Sebagian | W37: Perlu validasi plafond | Y37: Collect dokumen | Z37: Bottleneck tahap akhir. | AA37: Pipeline awal dominan | AB37: Bottleneck tahap akhir | AC37: Pipeline awal dominan
A38: CASE-00037 | B38: 46178 | C38: 2026-06 | D38: W1 | E38: RO ACEH | F38: ACEH TIMUR | G38: KC BANDA ACEH | H38: SPV Hendra Pratama | I38: Rizal Utami | J38: S0101001 | K38: Pra Pensiun | L38: Database Internal | M38: ASN | N38: Pemberkasan | O38: 5 | P38: 6 | Q38: Follow-up Telepon | R38: 46170 | S38: 33 | T38: 420000000 | U38: Belum Cair | V38: Lengkap | W38: Berkas perlu revisi | X38: Menunggu jadwal proses | Y38: Koordinasi cabang | Z38: Bottleneck tahap akhir. | AA38: Bottleneck tahap akhir | AB38: Bottleneck tahap akhir | AC38: Bottleneck tahap akhir
A39: CASE-00038 | B39: 46177 | C39: 2026-06 | D39: W1 | E39: RO MEDAN | F39: MEDAN KOTA | G39: KC MEDAN | H39: SPV Ulfa Saputra | I39: Ulfa Lestari | J39: S0203004 | K39: Mitraguna | L39: Database Internal | M39: Pra Pensiun | N39: Hangat | O39: 3 | P39: 6 | Q39: Kunjungan | R39: 46173 | S39: 30 | T39: 366000000 | U39: Belum Cair | V39: Belum Ada | W39: Perlu simulasi angsuran | Y39: Tetapkan next step | Z39: Butuh penguatan follow-up. | AA39: Kinerja seimbang | AB39: Butuh penguatan follow-up | AC39: Kinerja seimbang
A40: CASE-00039 | B40: 46186 | C40: 2026-06 | D40: W2 | E40: RO BANDUNG | F40: BANDUNG KOTA | G40: KC BANDUNG | H40: SPV Hani Kusuma | I40: Maya Rahman | J40: S0502001 | K40: Mitraguna | L40: Sapa Kebun | M40: Non Payroll | N40: Dingin | O40: 2 | P40: 12 | Q40: Follow-up Telepon | R40: 46180 | S40: 23 | T40: 255000000 | U40: Belum Cair | V40: Sebagian | W40: Minat masih rendah | Y40: Edukasi manfaat produk | Z40: Activity tinggi belum cair. | AA40: Konversi cukup baik | AB40: Activity tinggi belum cair | AC40: Konversi cukup baik
A41: CASE-00040 | B41: 46187 | C41: 2026-06 | D41: W2 | E41: RO JAKARTA 2 | F41: JAKARTA TIMUR | G41: KC BEKASI | H41: SPV Eka Ananda | I41: Kurnia Fauzi | J41: S0402004 | K41: Pensiun Berkah | L41: Referal Cabang | M41: Pensiunan | N41: Panas | O41: 4 | P41: 11 | Q41: Follow-up Telepon | R41: 46186 | S41: 17 | T41: 236000000 | U41: Belum Cair | V41: Sebagian | W41: Menunggu komitmen nasabah | X41: Menunggu kelengkapan dokumen | Y41: Collect dokumen | Z41: Bottleneck tahap akhir. | AA41: Activity tinggi namun hasil rendah | AB41: Bottleneck tahap akhir | AC41: Activity tinggi namun hasil rendah
A42: CASE-00041 | B42: 46191 | C42: 2026-06 | D42: W3 | E42: RO JAKARTA 2 | F42: JAKARTA SELATAN | G42: KCP PASAR MINGGU | H42: SPV Eka Ananda | I42: Hani Ananda | J42: S0402002 | K42: Pensiun Berkah | L42: Referal Cabang | M42: Payroll | N42: Hangat | O42: 3 | P42: 11 | Q42: Kunjungan | R42: 46181 | S42: 22 | T42: 272000000 | U42: Belum Cair | V42: Sebagian | W42: Menunggu keputusan keluarga | Y42: Tetapkan next step | Z42: Butuh penguatan follow-up. | AA42: Activity tinggi namun hasil rendah | AB42: Butuh penguatan follow-up | AC42: Activity tinggi namun hasil rendah
...

Sheet Summary_Check
A1: Sales Field Intelligence Data - Summary Check | B1: Sales Field Intelligence Dummy Data - Summary Check | C1: Sales Field Intelligence Dummy Data - Summary Check | D1: Sales Field Intelligence Dummy Data - Summary Check | E1: Sales Field Intelligence Dummy Data - Summary Check | F1: Sales Field Intelligence Dummy Data - Summary Check
A3: Total Rows | B3: =COUNTA(Pipeline_Activity_Data!$A:$A)-1 -> 2500
A4: Total Activity | B4: =SUM(Pipeline_Activity_Data!$P:$P) -> 23798
A5: Total Plafond | B5: =SUM(Pipeline_Activity_Data!$T:$T) -> 491331000000
A6: Jumlah Cair | B6: =COUNTIF(Pipeline_Activity_Data!$U:$U,"Cair")+COUNTIF(Pipeline_Activity_Data!$U:$U,"Sudah Cair")+COUNTIF(Pipeline_Activity_Data!$U:$U,"Terealisasi") -> 215
A7: Pipeline Tahap Awal | B7: =COUNTIF(Pipeline_Activity_Data!$N:$N,"Tidak Bertemu")+COUNTIF(Pipeline_Activity_Data!$N:$N,"Dingin") -> 700
A8: Pipeline Tahap Matang | B8: =COUNTIF(Pipeline_Activity_Data!$N:$N,"Panas")+COUNTIF(Pipeline_Activity_Data!$N:$N,"Pemberkasan")+COUNTIF(Pipeline_Activity_Data!$N:$N,"Perjanjian") -> 1068
A9: Periode | B9: 2026-06
A10: Jumlah Region | B10: =COUNTA(_xludf.UNIQUE(Pipeline_Activity_Data!$E$2:$E$2501)) -> 1
A13: Stage | B13: Jumlah Pipeline | C13: Total Activity | D13: Total Plafond
A14: Tidak Bertemu | B14: =COUNTIF(Pipeline_Activity_Data!$N:$N,A14) -> 311 | C14: =SUMIF(Pipeline_Activity_Data!$N:$N,A14,Pipeline_Activity_Data!$P:$P) -> 2289 | D14: =SUMIF(Pipeline_Activity_Data!$N:$N,A14,Pipeline_Activity_Data!$T:$T) -> 59113000000
A15: Dingin | B15: =COUNTIF(Pipeline_Activity_Data!$N:$N,A15) -> 389 | C15: =SUMIF(Pipeline_Activity_Data!$N:$N,A15,Pipeline_Activity_Data!$P:$P) -> 2995 | D15: =SUMIF(Pipeline_Activity_Data!$N:$N,A15,Pipeline_Activity_Data!$T:$T) -> 72399000000
A16: Hangat | B16: =COUNTIF(Pipeline_Activity_Data!$N:$N,A16) -> 517 | C16: =SUMIF(Pipeline_Activity_Data!$N:$N,A16,Pipeline_Activity_Data!$P:$P) -> 4229 | D16: =SUMIF(Pipeline_Activity_Data!$N:$N,A16,Pipeline_Activity_Data!$T:$T) -> 97748000000
A17: Panas | B17: =COUNTIF(Pipeline_Activity_Data!$N:$N,A17) -> 530 | C17: =SUMIF(Pipeline_Activity_Data!$N:$N,A17,Pipeline_Activity_Data!$P:$P) -> 5179 | D17: =SUMIF(Pipeline_Activity_Data!$N:$N,A17,Pipeline_Activity_Data!$T:$T) -> 107491000000
A18: Pemberkasan | B18: =COUNTIF(Pipeline_Activity_Data!$N:$N,A18) -> 360 | C18: =SUMIF(Pipeline_Activity_Data!$N:$N,A18,Pipeline_Activity_Data!$P:$P) -> 3960 | D18: =SUMIF(Pipeline_Activity_Data!$N:$N,A18,Pipeline_Activity_Data!$T:$T) -> 73052000000
A19: Perjanjian | B19: =COUNTIF(Pipeline_Activity_Data!$N:$N,A19) -> 178 | C19: =SUMIF(Pipeline_Activity_Data!$N:$N,A19,Pipeline_Activity_Data!$P:$P) -> 2157 | D19: =SUMIF(Pipeline_Activity_Data!$N:$N,A19,Pipeline_Activity_Data!$T:$T) -> 36290000000
A20: Cair | B20: =COUNTIF(Pipeline_Activity_Data!$N:$N,A20) -> 215 | C20: =SUMIF(Pipeline_Activity_Data!$N:$N,A20,Pipeline_Activity_Data!$P:$P) -> 2989 | D20: =SUMIF(Pipeline_Activity_Data!$N:$N,A20,Pipeline_Activity_Data!$T:$T) -> 45238000000

Sheet Data_Dictionary
A1: Kolom | B1: Tipe Data | C1: Wajib untuk Analyzer | D1: Keterangan
A2: Case ID | B2: Text | C2: Tidak | D2: ID unik untuk setiap baris pipeline.
A3: Tanggal | B3: Date | C3: Ya - periode | D3: Tanggal aktivitas atau update pipeline.
A4: Periode | B4: Text | C4: Ya - periode | D4: Format YYYY-MM untuk filter periode.
A5: Minggu | B5: Text | C5: Tidak | D5: Bucket minggu dalam bulan.
A6: Region | B6: Text | C6: Ya | D6: Region/RO untuk analisis wilayah.
A7: Area | B7: Text | C7: Opsional | D7: Area dalam region.
A8: Cabang | B8: Text | C8: Ya | D8: Cabang/KC/KCP terkait.
A9: Supervisor | B9: Text | C9: Ya | D9: Leader/Supervisor/KOREA/ASM untuk coaching.
A10: Sales | B10: Text | C10: Ya | D10: Nama Sales/SF.
A11: NIP Sales | B11: Text | C11: Tidak | D11: ID Sales
A12: Produk | B12: Text | C12: Opsional | D12: Produk pembiayaan.
... A30: Expected Insight Label | B30: Text | C30: Tidak | D30: Label ekspektasi insight untuk validasi manual.

Sheet Testing_Guide
A1: Sales Field Intelligence Testing Guide
A2: Tujuan
A3: Workbook ini dibuat untuk menguji Excel Analyzer, model router, RAG, dan chat loop Sales Field Intelligence Chatbot.
A4: Cara pakai di Colab
A5: 1. Upload file ini pada cell Excel Upload.
A6: 2. Pilih sheet Pipeline_Activity_Data.
A7: 3. Jalankan deteksi kolom, cleaning, summary, dan build excel_analysis_context.
A8: 4. Jalankan /excelstatus dan /quicksummary pada chat loop V2.
A9: 5. Uji pertanyaan berbasis data dan pastikan route menjadi excel_analyzer_gemini.
A10: Contoh Pertanyaan Testing
A11: Berdasarkan data Excel, buatkan ringkasan pipeline dan activity.
A12: Sales mana yang perlu menjadi prioritas coaching?
... A18: Chatbot harus menjawab berdasarkan summary data. Jika penyebab spesifik tidak tersedia, chatbot hanya boleh menyebut area validasi.

Sheet Expected_Patterns
A1: No | B1: Pola yang Ditanam | C1: Expected Route/Jawaban | D1: Catatan Validasi
A2: 1 | B2: RO SURABAYA 1 memiliki profil top performer | C2: Region ini cenderung muncul sebagai wilayah dengan konversi lebih baik | D2: Dibuat dengan stage Cair lebih tinggi daripada region lain
A3: 2 | B3: RO JAKARTA 1 didominasi stage awal | C3: Chatbot harus memberi rekomendasi validasi database dan follow-up awal | D3: Profil early_low_activity
A4: 3 | B4: RO JAKARTA 2 activity tinggi tetapi hasil rendah | C4: Chatbot harus menyoroti kualitas follow-up dan bottleneck | D4: Profil high_activity_low_result
A5: 4 | B5: RO ACEH memiliki pipeline matang tetapi bottleneck | C5: Chatbot harus menyoroti Panas/Pemberkasan yang perlu validasi | D5: Profil mature_bottleneck
A6: 5 | B6: Belum Cair/Batal Cair/Reject sengaja dibuat | C6: Analyzer tidak boleh menghitung Belum Cair sebagai Cair | D6: Untuk test fix is_cair
A7: 6 | B7: Kolom melebihi kebutuhan minimal | C7: Column detection tetap menemukan Sales, Supervisor, Region, Cabang, Stage, Activity, Status Cair, Plafond | D7: Untuk test fleksibilitas analyzer
A8: 7 | B8: Data memiliki kendala dan alasan reject | C8: Chatbot boleh menyebut area validasi, bukan mengarang penyebab di luar data | D8: Untuk test anti-halusinasi
